2022-09-17 09:15:59,209 INFO    MainThread:144134 [wandb_setup.py:_flush():68] Configure stats pid to 144134
2022-09-17 09:15:59,209 INFO    MainThread:144134 [wandb_setup.py:_flush():68] Loading settings from /home/fquesada/.config/wandb/settings
2022-09-17 09:15:59,209 INFO    MainThread:144134 [wandb_setup.py:_flush():68] Loading settings from /home/fquesada/Documents/LiteFlowNet_roya/wandb/settings
2022-09-17 09:15:59,209 INFO    MainThread:144134 [wandb_setup.py:_flush():68] Loading settings from environment variables: {'_require_service': 'True'}
2022-09-17 09:15:59,209 INFO    MainThread:144134 [wandb_setup.py:_flush():68] Inferring run settings from compute environment: {'program_relpath': 'main.py', 'program': '/home/fquesada/Documents/LiteFlowNet_roya/main.py'}
2022-09-17 09:15:59,210 INFO    MainThread:144134 [wandb_init.py:_log_setup():476] Logging user logs to /home/fquesada/Documents/LiteFlowNet_roya/wandb/run-20220917_091559-2/logs/debug.log
2022-09-17 09:15:59,210 INFO    MainThread:144134 [wandb_init.py:_log_setup():477] Logging internal logs to /home/fquesada/Documents/LiteFlowNet_roya/wandb/run-20220917_091559-2/logs/debug-internal.log
2022-09-17 09:15:59,210 INFO    MainThread:144134 [wandb_init.py:init():516] calling init triggers
2022-09-17 09:15:59,210 INFO    MainThread:144134 [wandb_init.py:init():519] wandb.init called with sweep_config: {}
config: {}
2022-09-17 09:15:59,211 INFO    MainThread:144134 [wandb_init.py:init():569] starting backend
2022-09-17 09:15:59,211 INFO    MainThread:144134 [wandb_init.py:init():573] setting up manager
2022-09-17 09:15:59,213 INFO    MainThread:144134 [backend.py:_multiprocessing_setup():102] multiprocessing start_methods=fork,spawn,forkserver, using: spawn
2022-09-17 09:15:59,215 INFO    MainThread:144134 [wandb_init.py:init():580] backend started and connected
2022-09-17 09:15:59,217 INFO    MainThread:144134 [wandb_init.py:init():658] updated telemetry
2022-09-17 09:15:59,221 INFO    MainThread:144134 [wandb_init.py:init():692] communicating run to backend with 30 second timeout
2022-09-17 09:16:23,319 ERROR   Thread-1 (wrapped_target):144134 [retry.py:__call__():154] Retry attempt failed:
Traceback (most recent call last):
  File "/home/fquesada/anaconda3/envs/roya_fquesada/lib/python3.10/site-packages/urllib3/connection.py", line 174, in _new_conn
    conn = connection.create_connection(
  File "/home/fquesada/anaconda3/envs/roya_fquesada/lib/python3.10/site-packages/urllib3/util/connection.py", line 72, in create_connection
    for res in socket.getaddrinfo(host, port, family, socket.SOCK_STREAM):
  File "/home/fquesada/anaconda3/envs/roya_fquesada/lib/python3.10/socket.py", line 955, in getaddrinfo
    for res in _socket.getaddrinfo(host, port, family, type, proto, flags):
socket.gaierror: [Errno -3] Temporary failure in name resolution

During handling of the above exception, another exception occurred:

Traceback (most recent call last):
  File "/home/fquesada/anaconda3/envs/roya_fquesada/lib/python3.10/site-packages/urllib3/connectionpool.py", line 703, in urlopen
    httplib_response = self._make_request(
  File "/home/fquesada/anaconda3/envs/roya_fquesada/lib/python3.10/site-packages/urllib3/connectionpool.py", line 386, in _make_request
    self._validate_conn(conn)
  File "/home/fquesada/anaconda3/envs/roya_fquesada/lib/python3.10/site-packages/urllib3/connectionpool.py", line 1042, in _validate_conn
    conn.connect()
  File "/home/fquesada/anaconda3/envs/roya_fquesada/lib/python3.10/site-packages/urllib3/connection.py", line 358, in connect
    self.sock = conn = self._new_conn()
  File "/home/fquesada/anaconda3/envs/roya_fquesada/lib/python3.10/site-packages/urllib3/connection.py", line 186, in _new_conn
    raise NewConnectionError(
urllib3.exceptions.NewConnectionError: <urllib3.connection.HTTPSConnection object at 0x7f36925aeec0>: Failed to establish a new connection: [Errno -3] Temporary failure in name resolution

During handling of the above exception, another exception occurred:

Traceback (most recent call last):
  File "/home/fquesada/anaconda3/envs/roya_fquesada/lib/python3.10/site-packages/requests/adapters.py", line 489, in send
    resp = conn.urlopen(
  File "/home/fquesada/anaconda3/envs/roya_fquesada/lib/python3.10/site-packages/urllib3/connectionpool.py", line 787, in urlopen
    retries = retries.increment(
  File "/home/fquesada/anaconda3/envs/roya_fquesada/lib/python3.10/site-packages/urllib3/util/retry.py", line 592, in increment
    raise MaxRetryError(_pool, url, error or ResponseError(cause))
urllib3.exceptions.MaxRetryError: HTTPSConnectionPool(host='api.wandb.ai', port=443): Max retries exceeded with url: /graphql (Caused by NewConnectionError('<urllib3.connection.HTTPSConnection object at 0x7f36925aeec0>: Failed to establish a new connection: [Errno -3] Temporary failure in name resolution'))

During handling of the above exception, another exception occurred:

Traceback (most recent call last):
  File "/home/fquesada/anaconda3/envs/roya_fquesada/lib/python3.10/site-packages/wandb/sdk/lib/retry.py", line 113, in __call__
    result = self._call_fn(*args, **kwargs)
  File "/home/fquesada/anaconda3/envs/roya_fquesada/lib/python3.10/site-packages/wandb/sdk/internal/internal_api.py", line 199, in execute
    return self.client.execute(*args, **kwargs)  # type: ignore
  File "/home/fquesada/anaconda3/envs/roya_fquesada/lib/python3.10/site-packages/wandb/vendor/gql-0.2.0/wandb_gql/client.py", line 52, in execute
    result = self._get_result(document, *args, **kwargs)
  File "/home/fquesada/anaconda3/envs/roya_fquesada/lib/python3.10/site-packages/wandb/vendor/gql-0.2.0/wandb_gql/client.py", line 60, in _get_result
    return self.transport.execute(document, *args, **kwargs)
  File "/home/fquesada/anaconda3/envs/roya_fquesada/lib/python3.10/site-packages/wandb/vendor/gql-0.2.0/wandb_gql/transport/requests.py", line 38, in execute
    request = requests.post(self.url, **post_args)
  File "/home/fquesada/anaconda3/envs/roya_fquesada/lib/python3.10/site-packages/requests/api.py", line 115, in post
    return request("post", url, data=data, json=json, **kwargs)
  File "/home/fquesada/anaconda3/envs/roya_fquesada/lib/python3.10/site-packages/requests/api.py", line 59, in request
    return session.request(method=method, url=url, **kwargs)
  File "/home/fquesada/anaconda3/envs/roya_fquesada/lib/python3.10/site-packages/requests/sessions.py", line 587, in request
    resp = self.send(prep, **send_kwargs)
  File "/home/fquesada/anaconda3/envs/roya_fquesada/lib/python3.10/site-packages/requests/sessions.py", line 701, in send
    r = adapter.send(request, **kwargs)
  File "/home/fquesada/anaconda3/envs/roya_fquesada/lib/python3.10/site-packages/requests/adapters.py", line 565, in send
    raise ConnectionError(e, request=request)
requests.exceptions.ConnectionError: HTTPSConnectionPool(host='api.wandb.ai', port=443): Max retries exceeded with url: /graphql (Caused by NewConnectionError('<urllib3.connection.HTTPSConnection object at 0x7f36925aeec0>: Failed to establish a new connection: [Errno -3] Temporary failure in name resolution'))
2022-09-17 09:16:29,234 ERROR   MainThread:144134 [wandb_init.py:init():703] backend process timed out
2022-09-17 09:16:29,234 ERROR   MainThread:144134 [wandb_init.py:init():712] encountered error: Error communicating with wandb process
For more info see: https://docs.wandb.ai/library/init#init-start-error
