2022-09-17 09:21:34,776 INFO    StreamThr :144196 [internal.py:wandb_internal():88] W&B internal server running at pid: 144196, started at: 2022-09-17 09:21:34.774894
2022-09-17 09:21:34,782 DEBUG   HandlerThread:144196 [handler.py:handle_request():138] handle_request: status
2022-09-17 09:21:34,785 DEBUG   SenderThread:144196 [sender.py:send_request():315] send_request: status
2022-09-17 09:21:34,788 INFO    WriterThread:144196 [datastore.py:open_for_write():75] open: /home/fquesada/Documents/LiteFlowNet_roya/wandb/run-20220917_092134-1/run-1.wandb
2022-09-17 09:21:34,788 DEBUG   SenderThread:144196 [sender.py:send():301] send: header
2022-09-17 09:21:34,788 DEBUG   SenderThread:144196 [sender.py:send():301] send: run
2022-09-17 09:21:34,791 INFO    SenderThread:144196 [sender.py:_maybe_setup_resume():577] checking resume status for None/roya_modelos/1
2022-09-17 09:22:03,201 ERROR   SenderThread:144196 [retry.py:__call__():154] Retry attempt failed:
Traceback (most recent call last):
  File "/home/fquesada/anaconda3/envs/roya_fquesada/lib/python3.10/site-packages/urllib3/connection.py", line 174, in _new_conn
    conn = connection.create_connection(
  File "/home/fquesada/anaconda3/envs/roya_fquesada/lib/python3.10/site-packages/urllib3/util/connection.py", line 72, in create_connection
    for res in socket.getaddrinfo(host, port, family, socket.SOCK_STREAM):
  File "/home/fquesada/anaconda3/envs/roya_fquesada/lib/python3.10/socket.py", line 955, in getaddrinfo
    for res in _socket.getaddrinfo(host, port, family, type, proto, flags):
socket.gaierror: [Errno -3] Temporary failure in name resolution

During handling of the above exception, another exception occurred:

Traceback (most recent call last):
  File "/home/fquesada/anaconda3/envs/roya_fquesada/lib/python3.10/site-packages/urllib3/connectionpool.py", line 703, in urlopen
    httplib_response = self._make_request(
  File "/home/fquesada/anaconda3/envs/roya_fquesada/lib/python3.10/site-packages/urllib3/connectionpool.py", line 386, in _make_request
    self._validate_conn(conn)
  File "/home/fquesada/anaconda3/envs/roya_fquesada/lib/python3.10/site-packages/urllib3/connectionpool.py", line 1042, in _validate_conn
    conn.connect()
  File "/home/fquesada/anaconda3/envs/roya_fquesada/lib/python3.10/site-packages/urllib3/connection.py", line 358, in connect
    self.sock = conn = self._new_conn()
  File "/home/fquesada/anaconda3/envs/roya_fquesada/lib/python3.10/site-packages/urllib3/connection.py", line 186, in _new_conn
    raise NewConnectionError(
urllib3.exceptions.NewConnectionError: <urllib3.connection.HTTPSConnection object at 0x7f49dc0e43d0>: Failed to establish a new connection: [Errno -3] Temporary failure in name resolution

During handling of the above exception, another exception occurred:

Traceback (most recent call last):
  File "/home/fquesada/anaconda3/envs/roya_fquesada/lib/python3.10/site-packages/requests/adapters.py", line 489, in send
    resp = conn.urlopen(
  File "/home/fquesada/anaconda3/envs/roya_fquesada/lib/python3.10/site-packages/urllib3/connectionpool.py", line 787, in urlopen
    retries = retries.increment(
  File "/home/fquesada/anaconda3/envs/roya_fquesada/lib/python3.10/site-packages/urllib3/util/retry.py", line 592, in increment
    raise MaxRetryError(_pool, url, error or ResponseError(cause))
urllib3.exceptions.MaxRetryError: HTTPSConnectionPool(host='api.wandb.ai', port=443): Max retries exceeded with url: /graphql (Caused by NewConnectionError('<urllib3.connection.HTTPSConnection object at 0x7f49dc0e43d0>: Failed to establish a new connection: [Errno -3] Temporary failure in name resolution'))

During handling of the above exception, another exception occurred:

Traceback (most recent call last):
  File "/home/fquesada/anaconda3/envs/roya_fquesada/lib/python3.10/site-packages/wandb/sdk/lib/retry.py", line 113, in __call__
    result = self._call_fn(*args, **kwargs)
  File "/home/fquesada/anaconda3/envs/roya_fquesada/lib/python3.10/site-packages/wandb/sdk/internal/internal_api.py", line 199, in execute
    return self.client.execute(*args, **kwargs)  # type: ignore
  File "/home/fquesada/anaconda3/envs/roya_fquesada/lib/python3.10/site-packages/wandb/vendor/gql-0.2.0/wandb_gql/client.py", line 52, in execute
    result = self._get_result(document, *args, **kwargs)
  File "/home/fquesada/anaconda3/envs/roya_fquesada/lib/python3.10/site-packages/wandb/vendor/gql-0.2.0/wandb_gql/client.py", line 60, in _get_result
    return self.transport.execute(document, *args, **kwargs)
  File "/home/fquesada/anaconda3/envs/roya_fquesada/lib/python3.10/site-packages/wandb/vendor/gql-0.2.0/wandb_gql/transport/requests.py", line 38, in execute
    request = requests.post(self.url, **post_args)
  File "/home/fquesada/anaconda3/envs/roya_fquesada/lib/python3.10/site-packages/requests/api.py", line 115, in post
    return request("post", url, data=data, json=json, **kwargs)
  File "/home/fquesada/anaconda3/envs/roya_fquesada/lib/python3.10/site-packages/requests/api.py", line 59, in request
    return session.request(method=method, url=url, **kwargs)
  File "/home/fquesada/anaconda3/envs/roya_fquesada/lib/python3.10/site-packages/requests/sessions.py", line 587, in request
    resp = self.send(prep, **send_kwargs)
  File "/home/fquesada/anaconda3/envs/roya_fquesada/lib/python3.10/site-packages/requests/sessions.py", line 701, in send
    r = adapter.send(request, **kwargs)
  File "/home/fquesada/anaconda3/envs/roya_fquesada/lib/python3.10/site-packages/requests/adapters.py", line 565, in send
    raise ConnectionError(e, request=request)
requests.exceptions.ConnectionError: HTTPSConnectionPool(host='api.wandb.ai', port=443): Max retries exceeded with url: /graphql (Caused by NewConnectionError('<urllib3.connection.HTTPSConnection object at 0x7f49dc0e43d0>: Failed to establish a new connection: [Errno -3] Temporary failure in name resolution'))
2022-09-17 09:22:04,796 DEBUG   HandlerThread:144196 [handler.py:handle_request():138] handle_request: poll_exit
2022-09-17 09:22:09,896 DEBUG   HandlerThread:144196 [handler.py:handle_request():138] handle_request: poll_exit
2022-09-17 09:22:14,997 DEBUG   HandlerThread:144196 [handler.py:handle_request():138] handle_request: poll_exit
2022-09-17 09:22:20,098 DEBUG   HandlerThread:144196 [handler.py:handle_request():138] handle_request: poll_exit
2022-09-17 09:22:25,199 DEBUG   HandlerThread:144196 [handler.py:handle_request():138] handle_request: poll_exit
2022-09-17 09:22:30,300 DEBUG   HandlerThread:144196 [handler.py:handle_request():138] handle_request: poll_exit
2022-09-17 09:22:35,401 DEBUG   HandlerThread:144196 [handler.py:handle_request():138] handle_request: poll_exit
2022-09-17 09:22:40,502 DEBUG   HandlerThread:144196 [handler.py:handle_request():138] handle_request: poll_exit
2022-09-17 09:22:45,603 DEBUG   HandlerThread:144196 [handler.py:handle_request():138] handle_request: poll_exit
2022-09-17 09:22:50,704 DEBUG   HandlerThread:144196 [handler.py:handle_request():138] handle_request: poll_exit
2022-09-17 09:22:55,805 DEBUG   HandlerThread:144196 [handler.py:handle_request():138] handle_request: poll_exit
2022-09-17 09:23:00,906 DEBUG   HandlerThread:144196 [handler.py:handle_request():138] handle_request: poll_exit
2022-09-17 09:23:06,007 DEBUG   HandlerThread:144196 [handler.py:handle_request():138] handle_request: poll_exit
2022-09-17 09:23:11,108 DEBUG   HandlerThread:144196 [handler.py:handle_request():138] handle_request: poll_exit
2022-09-17 09:23:16,209 DEBUG   HandlerThread:144196 [handler.py:handle_request():138] handle_request: poll_exit
2022-09-17 09:23:21,310 DEBUG   HandlerThread:144196 [handler.py:handle_request():138] handle_request: poll_exit
2022-09-17 09:23:26,411 DEBUG   HandlerThread:144196 [handler.py:handle_request():138] handle_request: poll_exit
2022-09-17 09:23:31,933 INFO    MainThread:144196 [internal.py:handle_exit():78] Internal process exited
2022-09-17 09:23:31,934 WARNING MsgRouterThr:144196 [router.py:message_loop():74] EOFError seen in message_loop
